Workbook

Sheet ReadMe
A1: Forward max-capacity-investment tool v2 — grounded historical, plan/IRENA ceilings, two forms, escalating headroom
A3: WHAT CHANGED (v2): the single 'MaxAdd' column was ambiguous. Now each stock curve carries its OWN year-over-year delta (the true max change in stock).
A5: SHEETS:
A6: Historical — end-2024 stock, the grounding (purple).
A7: Parameters — control panel (blue tunable). Headroom is now a RAMP: H_start (early) -> H_end (late), to widen the cap as forecast confidence drops.
A8: Trajectory — per series: Stock-Logistic, Stock-Geometric, and MaxAdd-Log(raw)=Stock-Log[y]-Stock-Log[y-1], MaxAdd-Geo(raw)=Stock-Geo[y]-Stock-Geo[y-1]. Pure deltas.
A9: Comparison — Original & Updated vs Tool pure-Logistic, pure-Geometric, and the MAX/MIN bracket (headroom-scaled). Charts plot the 4 key lines; the bracket = the span between Tool-Log & Tool-Geo.
A10: Export — DROP-IN, AnnualMaxCapacity_Final format. 8 blocks: pure Logistic, pure Geometric, LARGEST, SMALLEST — each RAW and HEADROOM-scaled. Copy whichever block.
A12: OPTIONS LOGIC: per year, LARGEST gap = MAX(logistic delta, geometric delta); SMALLEST gap = MIN(...). Logistic humps then tapers (saturation); geometric compounds then hits the L ceiling. So MAX gives the most room, MIN the least.
A13: RAW = pure delta (literal max change in stock). HEADROOM = raw x Headroom[y], where Headroom[y]=H_start+(H_end-H_start)*(y-2025)/25.
A15: KNOBS: L_2050 = ceiling (main anti-runaway + controls how hard the late tail falls). ym = inflection year. k = steepness. g/base = geometric growth. H_start/H_end = headroom ramp.
A16: CAVEAT: escalating headroom is a SECONDARY lever; if the late tail collapses it's because L is too low / ym too early — fix those first. Chile/Argentina/Peru ceilings are [EST] (plans gave generation-share, not GW).

Sheet Historical
A1: Historical year-end stock (GW)
A3: Year | B3: Brazil Utility solar | C3: Brazil Onshore wind | D3: Mexico Utility solar | E3: Mexico Onshore wind | F3: Chile Utility solar | G3: Chile Onshore wind | H3: Argentina Utility solar | I3: Argentina Onshore wind | J3: Colombia Utility solar | K3: Colombia Onshore wind | L3: Peru Utility solar | M3: Peru Onshore wind
A4: 2010 | B4: 0 | C4: 0.93 | D4: 0.03 | E4: 0.519 | F4: 0 | G4: 0.163 | H4: 0.006 | I4: 0.054 | J4: 0 | K4: 0.0195 | L4: 0 | M4: 0.0007
A5: 2011 | B5: 0 | C5: 1.43 | D5: 0.04 | E5: 0.601 | F5: 0 | G5: 0.184 | H5: 0.006 | I5: 0.054 | J5: 0 | K5: 0.0195 | L5: 0 | M5: 0.0007
A6: 2012 | B6: 0 | C6: 2.5 | D6: 0.07 | E6: 1.815 | F6: 0.002 | G6: 0.202 | H6: 0.008 | I6: 0.129 | J6: 0 | K6: 0.0195 | L6: 0.096 | M6: 0.0007
A7: 2013 | B7: 0 | C7: 3.47 | D7: 0.1 | E7: 2.122 | F7: 0.015 | G7: 0.301 | H7: 0.008 | I7: 0.187 | J7: 0 | K7: 0.0195 | L7: 0.096 | M7: 0.0007
A8: 2014 | B8: 0 | C8: 5.96 | D8: 0.07 | E8: 2.569 | F8: 0.22 | G8: 0.736 | H8: 0.008 | I8: 0.188 | J8: 0 | K8: 0.0184 | L8: 0.096 | M8: 0.142
A9: 2015 | B9: 0 | C9: 8.715 | D9: 0.15 | E9: 3.271 | F9: 0.55 | G9: 0.91 | H9: 0.0142 | I9: 0.1882 | J9: 0.0015 | K9: 0.018 | L9: 0.1349 | M9: 0.2398
A10: 2016 | B10: 0.1 | C10: 10.74 | D10: 0.36 | E10: 4.051 | F10: 1.08 | G10: 1.039 | H10: 0.0137 | I10: 0.1882 | J10: 0.0015 | K10: 0.018 | L10: 0.1461 | M10: 0.24
A11: 2017 | B11: 1.1 | C11: 12.76 | D11: 0.67 | E11: 4.18 | F11: 1.64 | G11: 1.302 | H11: 0.0136 | I11: 0.2276 | J11: 0.0113 | K11: 0.018 | L11: 0.2979 | M11: 0.24
A12: 2018 | B12: 1.6 | C12: 14.71 | D12: 2.06 | E12: 4.18 | F12: 2.15 | G12: 1.692 | H12: 0.1961 | I12: 0.7512 | J12: 0.0134 | K12: 0.018 | L12: 0.3242 | M12: 0.3723
A13: 2019 | B13: 2.4 | C13: 15.45 | D13: 5.25 | E13: 6.541 | F13: 2.5 | G13: 1.999 | H13: 0.4459 | I13: 1.6095 | J13: 0.0231 | K13: 0.0184 | L13: 0.3348 | M13: 0.3723
A14: 2020 | B14: 3.5 | C14: 17.75 | D14: 5.59 | E14: 6.995 | F14: 2.9 | G14: 2.293 | H14: 0.7679 | I14: 2.624 | J14: 0.0827 | K14: 0.0184 | L14: 0.3348 | M14: 0.409
A15: 2021 | B15: 4.9 | C15: 21.5 | D15: 6.87 | E15: 7.469 | F15: 3.9 | G15: 3.14 | H15: 1.0769 | I15: 3.2922 | J15: 0.181 | K15: 0.0184 | L15: 0.3323 | M15: 0.409
... A18: 2024 | B18: 16.6 | C18: 32 | D18: 7.52 | E18: 7.318 | F18: 7.6 | G18: 4.717 | H18: 1.7406 | I18: 4.3203 | J18: 1.3925 | K18: 0.0338 | L18: 0.5277 | M18: 1.1507
A20: Primary source | B20: IRENA RCS25 (Δ); ABSOLAR/ANEEL/ONS | C20: IRENA RCS25 (Δ); GWEC/ABEEólica/ANEEL | D20: IRENA RCS25 (Δ); CRE/Asolmex | E20: IRENA RCS25 (Δ); AMDEE | F20: IRENA RCS25 (Δ); CEN/CNE/ACERA | G20: IRENA RCS25 (Δ); CEN/CNE/ACERA | H20: IRENA RCS25 (Δ); CAMMESA/Sec.Energía | I20: IRENA RCS25 (Δ); CAMMESA/Sec.Energía | J20: IRENA RCS25 (Δ); XM/UPME/SER | K20: IRENA RCS25 (Δ); XM/UPME | L20: IRENA RCS25 (Δ); COES/MINEM/SPR | M20: IRENA RCS25 (Δ); COES/MINEM/Osinergmin
A21: Provenance / caveat | B21: util/dist split 2016-21 [EST] | C21: 2012-14,16-17,19-20,22-23 [EST] | D21: firm (IRENA) | E21: IRENA vs AMDEE >15% (2019,2023) | F21: firm (IRENA); util=IRENA−PMGD | G21: firm (IRENA) | H21: pre-2015 [EST] | I21: pre-2015 [EST] | J21: 2024 IRENA vs SER (AC/DC) | K21: firm (IRENA) | L21: 2024 AC vs DC | M21: firm (IRENA)
A23: Backbone: IRENA Renewable Capacity Statistics 2025 (year-end stock; additions = year-over-year Δ). Full references & links on 'Sources' sheet.
A24: IRENA RCS 2025 → | B24: https://www.irena.org/Publications/2025/Mar/Renewable-capacity-statistics-2025

Sheet Parameters
A1: Parameters — control panel (blue = tunable)
A3: Key | B3: Country | C3: Tech | D3: Stock2024 | E3: Base(recent) | F3: Form | G3: L_2050 | H3: WP2030 | I3: k | J3: ym | K3: g | L3: H_start | M3: H_end | N3: Justification | O3: Source
A4: BRA_sol | B4: Brazil | C4: Utility solar | D4: 16.6 | E4: 3.84 | F4: Logistic | G4: 100 | H4: 35 | I4: 0.18 | J4: 2035 | K4: 0.06 | L4: 1.2 | M4: 1.5 | N4: PDE2034 ~35GW@34; PNE2050 35-196, ceiling mid | O4: EPE PDE2034/PNE2050
A5: BRA_wind | B5: Brazil | C5: Onshore wind | D5: 32 | E5: 3.92 | F5: Logistic | G5: 120 | H5: 50 | I5: 0.16 | J5: 2033 | K5: 0.05 | L5: 1.2 | M5: 1.5 | N5: PDE2034 ~50GW@34; PNE2050 potential 143 | O5: EPE PDE2034/PNE2050
A6: MEX_sol | B6: Mexico | C6: Utility solar | D6: 7.52 | E6: 0.22 | F6: Logistic | G6: 40 | H6: 23 | I6: 0.2 | J6: 2036 | K6: 0.08 | L6: 1.3 | M6: 1.6 | N6: PRODESEN ~23@30 ~25@38; base~0 post-auction | O6: SENER PRODESEN24-38
A7: MEX_wind | B7: Mexico | C7: Onshore wind | D7: 7.318 | E7: 0 | F7: Logistic | G7: 45 | H7: 12 | I7: 0.2 | J7: 2037 | K7: 0.08 | L7: 1.3 | M7: 1.6 | N7: PRODESEN ~12@30 ~33-35@38; base~0 | O7: SENER PRODESEN24-38
A8: CHL_sol | B8: Chile | C8: Utility solar | D8: 7.6 | E8: 1.23 | F8: Logistic | G8: 45 | H8: 15 | I8: 0.18 | J8: 2035 | K8: 0.06 | L8: 1.2 | M8: 1.5 | N8: PELP share+UChile >5x by50 [EST] | O8: MinEnergia PELP [EST]
A9: CHL_wind | B9: Chile | C9: Onshore wind | D9: 4.717 | E9: 0.526 | F9: Logistic | G9: 30 | H9: 8 | I9: 0.16 | J9: 2035 | K9: 0.06 | L9: 1.2 | M9: 1.5 | N9: PELP share+UChile [EST] | O9: MinEnergia PELP [EST]
A10: ARG_sol | B10: Argentina | C10: Utility solar | D10: 1.7406 | E10: 0.221 | F10: Logistic | G10: 12 | H10: 3 | I10: 0.18 | J10: 2037 | K10: 0.07 | L10: 1.3 | M10: 1.6 | N10: Plan Transicion adds only; ceiling [EST] | O10: Sec.Energia [EST]
A11: ARG_wind | B11: Argentina | C11: Onshore wind | D11: 4.3203 | E11: 0.343 | F11: Logistic | G11: 25 | H11: 7 | I11: 0.16 | J11: 2036 | K11: 0.06 | L11: 1.25 | M11: 1.55 | N11: REN30 +6GW wind@30; 2050 [EST] | O11: Sec.Energia [EST]
A12: COL_sol | B12: Colombia | C12: Utility solar | D12: 1.3925 | E12: 0.404 | F12: Logistic | G12: 28 | H12: 6 | I12: 0.2 | J12: 2036 | K12: 0.1 | L12: 1.3 | M12: 1.6 | N12: Govt 6GW; PEN2052 25-30.9 | O12: UPME PEN2022-2052
A13: COL_wind | B13: Colombia | C13: Onshore wind | D13: 0.0338 | E13: 0.005 | F13: Logistic | G13: 7 | H13: 3 | I13: 0.22 | J13: 2034 | K13: 0.1 | L13: 1.4 | M13: 1.7 | N13: Frozen to Colectora I; PEN2052 onshore 7 | O13: UPME PEN2022-2052
A14: PER_sol | B14: Peru | C14: Utility solar | D14: 0.5277 | E14: 0.065 | F14: Logistic | G14: 8 | H14: 2.3 | I14: 0.18 | J14: 2037 | K14: 0.1 | L14: 1.3 | M14: 1.6 | N14: Osinergmin pipeline ~2.3@30; 2050 [EST] | O14: MINEM/Osinergmin [EST]
A15: PER_wind | B15: Peru | C15: Onshore wind | D15: 1.1507 | E15: 0.247 | F15: Logistic | G15: 6 | H15: 1.5 | I15: 0.16 | J15: 2036 | K15: 0.08 | L15: 1.25 | M15: 1.55 | N15: pipeline ~0.6-1.0@30; 2050 [EST] | O15: MINEM/Osinergmin [EST]
A17: Forward anchors & full citations on 'Sources' sheet. Source cells link to the plan/report.

Sheet Trajectory
A1: Trajectory — Stock (both forms) + each form's own delta (MaxAdd raw = max change in stock). 2010-2050.
B2: Brazil Utility solar | F2: Brazil Onshore wind | J2: Mexico Utility solar | N2: Mexico Onshore wind | R2: Chile Utility solar | V2: Chile Onshore wind | Z2: Argentina Utility solar | AD2: Argentina Onshore wind | AH2: Colombia Utility solar | AL2: Colombia Onshore wind | AP2: Peru Utility solar | AT2: Peru Onshore wind
A3: Year | B3: Stock-Log | C3: Stock-Geo | D3: MaxAdd-Log(raw) | E3: MaxAdd-Geo(raw) | F3: Stock-Log | G3: Stock-Geo | H3: MaxAdd-Log(raw) | I3: MaxAdd-Geo(raw) | J3: Stock-Log | K3: Stock-Geo | L3: MaxAdd-Log(raw) | M3: MaxAdd-Geo(raw) | N3: Stock-Log | O3: Stock-Geo | P3: MaxAdd-Log(raw) | Q3: MaxAdd-Geo(raw) | R3: Stock-Log | S3: Stock-Geo | T3: MaxAdd-Log(raw) | U3: MaxAdd-Geo(raw) | V3: Stock-Log | W3: Stock-Geo | X3: MaxAdd-Log(raw) | Y3: MaxAdd-Geo(raw) | Z3: Stock-Log | AA3: Stock-Geo | AB3: MaxAdd-Log(raw) | AC3: MaxAdd-Geo(raw) | AD3: Stock-Log | AE3: Stock-Geo | AF3: MaxAdd-Log(raw) | AG3: MaxAdd-Geo(raw) | AH3: Stock-Log | AI3: Stock-Geo | AJ3: MaxAdd-Log(raw) | AK3: MaxAdd-Geo(raw) | AL3: Stock-Log | AM3: Stock-Geo | AN3: MaxAdd-Log(raw) | AO3: MaxAdd-Geo(raw) | AP3: Stock-Log | AQ3: Stock-Geo | AR3: MaxAdd-Log(raw) | AS3: MaxAdd-Geo(raw) | AT3: Stock-Log | AU3: Stock-Geo | AV3: MaxAdd-Log(raw) | AW3: MaxAdd-Geo(raw)
A4: 2010 | B4: 0 | C4: 0 | F4: 0.93 | G4: 0.93 | J4: 0.03 | K4: 0.03 | N4: 0.519 | O4: 0.519 | R4: 0 | S4: 0 | V4: 0.163 | W4: 0.163 | Z4: 0.006 | AA4: 0.006 | AD4: 0.054 | AE4: 0.054 | AH4: 0 | AI4: 0 | AL4: 0.0195 | AM4: 0.0195 | AP4: 0 | AQ4: 0 | AT4: 0.0007 | AU4: 0.0007
A5: 2011 | B5: 0 | C5: 0 | D5: =MAX(B5-B4,0) -> 0 | E5: =MAX(C5-C4,0) -> 0 | F5: 1.43 | G5: 1.43 | H5: =MAX(F5-F4,0) -> 0.5 | I5: =MAX(G5-G4,0) -> 0.5 | J5: 0.04 | K5: 0.04 | L5: =MAX(J5-J4,0) -> 0.01 | M5: =MAX(K5-K4,0) -> 0.01 | N5: 0.601 | O5: 0.601 | P5: =MAX(N5-N4,0) -> 0.082 | Q5: =MAX(O5-O4,0) -> 0.082 | R5: 0 | S5: 0 | T5: =MAX(R5-R4,0) -> 0 | U5: =MAX(S5-S4,0) -> 0 | V5: 0.184 | W5: 0.184 | X5: =MAX(V5-V4,0) -> 0.021 | Y5: =MAX(W5-W4,0) -> 0.021 | Z5: 0.006 | AA5: 0.006 | AB5: =MAX(Z5-Z4,0) -> 0 | AC5: =MAX(AA5-AA4,0) -> 0 | AD5: 0.054 | AE5: 0.054 | AF5: =MAX(AD5-AD4,0) -> 0 | AG5: =MAX(AE5-AE4,0) -> 0 | AH5: 0 | AI5: 0 | AJ5: =MAX(AH5-AH4,0) -> 0 | AK5: =MAX(AI5-AI4,0) -> 0 | AL5: 0.0195 | AM5: 0.0195 | AN5: =MAX(AL5-AL4,0) -> 0 | AO5: =MAX(AM5-AM4,0) -> 0 | AP5: 0 | AQ5: 0 | AR5: =MAX(AP5-AP4,0) -> 0 | AS5: =MAX(AQ5-AQ4,0) -> 0 | AT5: 0.0007 | AU5: 0.0007 | AV5: =MAX(AT5-AT4,0) -> 0 | AW5: =MAX(AU5-AU4,0) -> 0
A6: 2012 | B6: 0 | C6: 0 | D6: =MAX(B6-B5,0) -> 0 | E6: =MAX(C6-C5,0) -> 0 | F6: 2.5 | G6: 2.5 | H6: =MAX(F6-F5,0) -> 1.07 | I6: =MAX(G6-G5,0) -> 1.07 | J6: 0.07 | K6: 0.07 | L6: =MAX(J6-J5,0) -> 0.03 | M6: =MAX(K6-K5,0) -> 0.03 | N6: 1.815 | O6: 1.815 | P6: =MAX(N6-N5,0) -> 1.214 | Q6: =MAX(O6-O5,0) -> 1.214 | R6: 0.002 | S6: 0.002 | T6: =MAX(R6-R5,0) -> 0.002 | U6: =MAX(S6-S5,0) -> 0.002 | V6: 0.202 | W6: 0.202 | X6: =MAX(V6-V5,0) -> 0.018 | Y6: =MAX(W6-W5,0) -> 0.018 | Z6: 0.008 | AA6: 0.008 | AB6: =MAX(Z6-Z5,0) -> 0.002 | AC6: =MAX(AA6-AA5,0) -> 0.002 | AD6: 0.129 | AE6: 0.129 | AF6: =MAX(AD6-AD5,0) -> 0.075 | AG6: =MAX(AE6-AE5,0) -> 0.075 | AH6: 0 | AI6: 0 | AJ6: =MAX(AH6-AH5,0) -> 0 | AK6: =MAX(AI6-AI5,0) -> 0 | AL6: 0.0195 | AM6: 0.0195 | AN6: =MAX(AL6-AL5,0) -> 0 | AO6: =MAX(AM6-AM5,0) -> 0 | AP6: 0.096 | AQ6: 0.096 | AR6: =MAX(AP6-AP5,0) -> 0.096 | AS6: =MAX(AQ6-AQ5,0) -> 0.096 | AT6: 0.0007 | AU6: 0.0007 | AV6: =MAX(AT6-AT5,0) -> 0 | AW6: =MAX(AU6-AU5,0) -> 0
A7: 2013 | B7: 0 | C7: 0 | D7: =MAX(B7-B6,0) -> 0 | E7: =MAX(C7-C6,0) -> 0 | F7: 3.47 | G7: 3.47 | H7: =MAX(F7-F6,0) -> 0.97 | I7: =MAX(G7-G6,0) -> 0.97 | J7: 0.1 | K7: 0.1 | L7: =MAX(J7-J6,0) -> 0.03 | M7: =MAX(K7-K6,0) -> 0.03 | N7: 2.122 | O7: 2.122 | P7: =MAX(N7-N6,0) -> 0.307 | Q7: =MAX(O7-O6,0) -> 0.307 | R7: 0.015 | S7: 0.015 | T7: =MAX(R7-R6,0) -> 0.013 | U7: =MAX(S7-S6,0) -> 0.013 | V7: 0.301 | W7: 0.301 | X7: =MAX(V7-V6,0) -> 0.099 | Y7: =MAX(W7-W6,0) -> 0.099 | Z7: 0.008 | AA7: 0.008 | AB7: =MAX(Z7-Z6,0) -> 0 | AC7: =MAX(AA7-AA6,0) -> 0 | AD7: 0.187 | AE7: 0.187 | AF7: =MAX(AD7-AD6,0) -> 0.058 | AG7: =MAX(AE7-AE6,0) -> 0.058 | AH7: 0 | AI7: 0 | AJ7: =MAX(AH7-AH6,0) -> 0 | AK7: =MAX(AI7-AI6,0) -> 0 | AL7: 0.0195 | AM7: 0.0195 | AN7: =MAX(AL7-AL6,0) -> 0 | AO7: =MAX(AM7-AM6,0) -> 0 | AP7: 0.096 | AQ7: 0.096 | AR7: =MAX(AP7-AP6,0) -> 0 | AS7: =MAX(AQ7-AQ6,0) -> 0 | AT7: 0.0007 | AU7: 0.0007 | AV7: =MAX(AT7-AT6,0) -> 0 | AW7: =MAX(AU7-AU6,0) -> 0
A8: 2014 | B8: 0 | C8: 0 | D8: =MAX(B8-B7,0) -> 0 | E8: =MAX(C8-C7,0) -> 0 | F8: 5.96 | G8: 5.96 | H8: =MAX(F8-F7,0) -> 2.49 | I8: =MAX(G8-G7,0) -> 2.49 | J8: 0.07 | K8: 0.07 | L8: =MAX(J8-J7,0) -> 0 | M8: =MAX(K8-K7,0) -> 0 | N8: 2.569 | O8: 2.569 | P8: =MAX(N8-N7,0) -> 0.447 | Q8: =MAX(O8-O7,0) -> 0.447 | R8: 0.22 | S8: 0.22 | T8: =MAX(R8-R7,0) -> 0.205 | U8: =MAX(S8-S7,0) -> 0.205 | V8: 0.736 | W8: 0.736 | X8: =MAX(V8-V7,0) -> 0.435 | Y8: =MAX(W8-W7,0) -> 0.435 | Z8: 0.008 | AA8: 0.008 | AB8: =MAX(Z8-Z7,0) -> 0 | AC8: =MAX(AA8-AA7,0) -> 0 | AD8: 0.188 | AE8: 0.188 | AF8: =MAX(AD8-AD7,0) -> 0.001 | AG8: =MAX(AE8-AE7,0) -> 0.001 | AH8: 0 | AI8: 0 | AJ8: =MAX(AH8-AH7,0) -> 0 | AK8: =MAX(AI8-AI7,0) -> 0 | AL8: 0.0184 | AM8: 0.0184 | AN8: =MAX(AL8-AL7,0) -> 0 | AO8: =MAX(AM8-AM7,0) -> 0 | AP8: 0.096 | AQ8: 0.096 | AR8: =MAX(AP8-AP7,0) -> 0 | AS8: =MAX(AQ8-AQ7,0) -> 0 | AT8: 0.142 | AU8: 0.142 | AV8: =MAX(AT8-AT7,0) -> 0.1413 | AW8: =MAX(AU8-AU7,0) -> 0.1413
A9: 2015 | B9: 0 | C9: 0 | D9: =MAX(B9-B8,0) -> 0 | E9: =MAX(C9-C8,0) -> 0 | F9: 8.715 | G9: 8.715 | H9: =MAX(F9-F8,0) -> 2.755 | I9: =MAX(G9-G8,0) -> 2.755 | J9: 0.15 | K9: 0.15 | L9: =MAX(J9-J8,0) -> 0.08 | M9: =MAX(K9-K8,0) -> 0.08 | N9: 3.271 | O9: 3.271 | P9: =MAX(N9-N8,0) -> 0.702 | Q9: =MAX(O9-O8,0) -> 0.702 | R9: 0.55 | S9: 0.55 | T9: =MAX(R9-R8,0) -> 0.33 | U9: =MAX(S9-S8,0) -> 0.33 | V9: 0.91 | W9: 0.91 | X9: =MAX(V9-V8,0) -> 0.174 | Y9: =MAX(W9-W8,0) -> 0.174 | Z9: 0.0142 | AA9: 0.0142 | AB9: =MAX(Z9-Z8,0) -> 0.0062 | AC9: =MAX(AA9-AA8,0) -> 0.0062 | AD9: 0.1882 | AE9: 0.1882 | AF9: =MAX(AD9-AD8,0) -> 0.0002 | AG9: =MAX(AE9-AE8,0) -> 0.0002 | AH9: 0.0015 | AI9: 0.0015 | AJ9: =MAX(AH9-AH8,0) -> 0.0015 | AK9: =MAX(AI9-AI8,0) -> 0.0015 | AL9: 0.018 | AM9: 0.018 | AN9: =MAX(AL9-AL8,0) -> 0 | AO9: =MAX(AM9-AM8,0) -> 0 | AP9: 0.1349 | AQ9: 0.1349 | AR9: =MAX(AP9-AP8,0) -> 0.0389 | AS9: =MAX(AQ9-AQ8,0) -> 0.0389 | AT9: 0.2398 | AU9: 0.2398 | AV9: =MAX(AT9-AT8,0) -> 0.0978 | AW9: =MAX(AU9-AU8,0) -> 0.0978
A10: 2016 | B10: 0.1 | C10: 0.1 | D10: =MAX(B10-B9,0) -> 0.1 | E10: =MAX(C10-C9,0) -> 0.1 | F10: 10.74 | G10: 10.74 | H10: =MAX(F10-F9,0) -> 2.025 | I10: =MAX(G10-G9,0) -> 2.025 | J10: 0.36 | K10: 0.36 | L10: =MAX(J10-J9,0) -> 0.21 | M10: =MAX(K10-K9,0) -> 0.21 | N10: 4.051 | O10: 4.051 | P10: =MAX(N10-N9,0) -> 0.78 | Q10: =MAX(O10-O9,0) -> 0.78 | R10: 1.08 | S10: 1.08 | T10: =MAX(R10-R9,0) -> 0.53 | U10: =MAX(S10-S9,0) -> 0.53 | V10: 1.039 | W10: 1.039 | X10: =MAX(V10-V9,0) -> 0.129 | Y10: =MAX(W10-W9,0) -> 0.129 | Z10: 0.0137 | AA10: 0.0137 | AB10: =MAX(Z10-Z9,0) -> 0 | AC10: =MAX(AA10-AA9,0) -> 0 | AD10: 0.1882 | AE10: 0.1882 | AF10: =MAX(AD10-AD9,0) -> 0 | AG10: =MAX(AE10-AE9,0) -> 0 | AH10: 0.0015 | AI10: 0.0015 | AJ10: =MAX(AH10-AH9,0) -> 0 | AK10: =MAX(AI10-AI9,0) -> 0 | AL10: 0.018 | AM10: 0.018 | AN10: =MAX(AL10-AL9,0) -> 0 | AO10: =MAX(AM10-AM9,0) -> 0 | AP10: 0.1461 | AQ10: 0.1461 | AR10: =MAX(AP10-AP9,0) -> 0.0112 | AS10: =MAX(AQ10-AQ9,0) -> 0.0112 | AT10: 0.24 | AU10: 0.24 | AV10: =MAX(AT10-AT9,0) -> 0.0002 | AW10: =MAX(AU10-AU9,0) -> 0.0002
A11: 2017 | B11: 1.1 | C11: 1.1 | D11: =MAX(B11-B10,0) -> 1 | E11: =MAX(C11-C10,0) -> 1 | F11: 12.76 | G11: 12.76 | H11: =MAX(F11-F10,0) -> 2.02 | I11: =MAX(G11-G10,0) -> 2.02 | J11: 0.67 | K11: 0.67 | L11: =MAX(J11-J10,0) -> 0.31 | M11: =MAX(K11-K10,0) -> 0.31 | N11: 4.18 | O11: 4.18 | P11: =MAX(N11-N10,0) -> 0.129 | Q11: =MAX(O11-O10,0) -> 0.129 | R11: 1.64 | S11: 1.64 | T11: =MAX(R11-R10,0) -> 0.56 | U11: =MAX(S11-S10,0) -> 0.56 | V11: 1.302 | W11: 1.302 | X11: =MAX(V11-V10,0) -> 0.263 | Y11: =MAX(W11-W10,0) -> 0.263 | Z11: 0.0136 | AA11: 0.0136 | AB11: =MAX(Z11-Z10,0) -> 0 | AC11: =MAX(AA11-AA10,0) -> 0 | AD11: 0.2276 | AE11: 0.2276 | AF11: =MAX(AD11-AD10,0) -> 0.0394 | AG11: =MAX(AE11-AE10,0) -> 0.0394 | AH11: 0.0113 | AI11: 0.0113 | AJ11: =MAX(AH11-AH10,0) -> 0.0098 | AK11: =MAX(AI11-AI10,0) -> 0.0098 | AL11: 0.018 | AM11: 0.018 | AN11: =MAX(AL11-AL10,0) -> 0 | AO11: =MAX(AM11-AM10,0) -> 0 | AP11: 0.2979 | AQ11: 0.2979 | AR11: =MAX(AP11-AP10,0) -> 0.1518 | AS11: =MAX(AQ11-AQ10,0) -> 0.1518 | AT11: 0.24 | AU11: 0.24 | AV11: =MAX(AT11-AT10,0) -> 0 | AW11: =MAX(AU11-AU10,0) -> 0
A12: 2018 | B12: 1.6 | C12: 1.6 | D12: =MAX(B12-B11,0) -> 0.5 | E12: =MAX(C12-C11,0) -> 0.5 | F12: 14.71 | G12: 14.71 | H12: =MAX(F12-F11,0) -> 1.95 | I12: =MAX(G12-G11,0) -> 1.95 | J12: 2.06 | K12: 2.06 | L12: =MAX(J12-J11,0) -> 1.39 | M12: =MAX(K12-K11,0) -> 1.39 | N12: 4.18 | O12: 4.18 | P12: =MAX(N12-N11,0) -> 0 | Q12: =MAX(O12-O11,0) -> 0 | R12: 2.15 | S12: 2.15 | T12: =MAX(R12-R11,0) -> 0.51 | U12: =MAX(S12-S11,0) -> 0.51 | V12: 1.692 | W12: 1.692 | X12: =MAX(V12-V11,0) -> 0.39 | Y12: =MAX(W12-W11,0) -> 0.39 | Z12: 0.1961 | AA12: 0.1961 | AB12: =MAX(Z12-Z11,0) -> 0.1825 | AC12: =MAX(AA12-AA11,0) -> 0.1825 | AD12: 0.7512 | AE12: 0.7512 | AF12: =MAX(AD12-AD11,0) -> 0.5236 | AG12: =MAX(AE12-AE11,0) -> 0.5236 | AH12: 0.0134 | AI12: 0.0134 | AJ12: =MAX(AH12-AH11,0) -> 0.0021 | AK12: =MAX(AI12-AI11,0) -> 0.0021 | AL12: 0.018 | AM12: 0.018 | AN12: =MAX(AL12-AL11,0) -> 0 | AO12: =MAX(AM12-AM11,0) -> 0 | AP12: 0.3242 | AQ12: 0.3242 | AR12: =MAX(AP12-AP11,0) -> 0.0263 | AS12: =MAX(AQ12-AQ11,0) -> 0.0263 | AT12: 0.3723 | AU12: 0.3723 | AV12: =MAX(AT12-AT11,0) -> 0.1323 | AW12: =MAX(AU12-AU11,0) -> 0.1323
A13: 2019 | B13: 2.4 | C13: 2.4 | D13: =MAX(B13-B12,0) -> 0.8 | E13: =MAX(C13-C12,0) -> 0.8 | F13: 15.45 | G13: 15.45 | H13: =MAX(F13-F12,0) -> 0.74 | I13: =MAX(G13-G12,0) -> 0.74 | J13: 5.25 | K13: 5.25 | L13: =MAX(J13-J12,0) -> 3.19 | M13: =MAX(K13-K12,0) -> 3.19 | N13: 6.541 | O13: 6.541 | P13: =MAX(N13-N12,0) -> 2.361 | Q13: =MAX(O13-O12,0) -> 2.361 | R13: 2.5 | S13: 2.5 | T13: =MAX(R13-R12,0) -> 0.35 | U13: =MAX(S13-S12,0) -> 0.35 | V13: 1.999 | W13: 1.999 | X13: =MAX(V13-V12,0) -> 0.307 | Y13: =MAX(W13-W12,0) -> 0.307 | Z13: 0.4459 | AA13: 0.4459 | AB13: =MAX(Z13-Z12,0) -> 0.2498 | AC13: =MAX(AA13-AA12,0) -> 0.2498 | AD13: 1.6095 | AE13: 1.6095 | AF13: =MAX(AD13-AD12,0) -> 0.8583 | AG13: =MAX(AE13-AE12,0) -> 0.8583 | AH13: 0.0231 | AI13: 0.0231 | AJ13: =MAX(AH13-AH12,0) -> 0.0097 | AK13: =MAX(AI13-AI12,0) -> 0.0097 | AL13: 0.0184 | AM13: 0.0184 | AN13: =MAX(AL13-AL12,0) -> 0.0004 | AO13: =MAX(AM13-AM12,0) -> 0.0004 | AP13: 0.3348 | AQ13: 0.3348 | AR13: =MAX(AP13-AP12,0) -> 0.0106 | AS13: =MAX(AQ13-AQ12,0) -> 0.0106 | AT13: 0.3723 | AU13: 0.3723 | AV13: =MAX(AT13-AT12,0) -> 0 | AW13: =MAX(AU13-AU12,0) -> 0
A14: 2020 | B14: 3.5 | C14: 3.5 | D14: =MAX(B14-B13,0) -> 1.1 | E14: =MAX(C14-C13,0) -> 1.1 | F14: 17.75 | G14: 17.75 | H14: =MAX(F14-F13,0) -> 2.3 | I14: =MAX(G14-G13,0) -> 2.3 | J14: 5.59 | K14: 5.59 | L14: =MAX(J14-J13,0) -> 0.34 | M14: =MAX(K14-K13,0) -> 0.34 | N14: 6.995 | O14: 6.995 | P14: =MAX(N14-N13,0) -> 0.454 | Q14: =MAX(O14-O13,0) -> 0.454 | R14: 2.9 | S14: 2.9 | T14: =MAX(R14-R13,0) -> 0.4 | U14: =MAX(S14-S13,0) -> 0.4 | V14: 2.293 | W14: 2.293 | X14: =MAX(V14-V13,0) -> 0.294 | Y14: =MAX(W14-W13,0) -> 0.294 | Z14: 0.7679 | AA14: 0.7679 | AB14: =MAX(Z14-Z13,0) -> 0.322 | AC14: =MAX(AA14-AA13,0) -> 0.322 | AD14: 2.624 | AE14: 2.624 | AF14: =MAX(AD14-AD13,0) -> 1.0145 | AG14: =MAX(AE14-AE13,0) -> 1.0145 | AH14: 0.0827 | AI14: 0.0827 | AJ14: =MAX(AH14-AH13,0) -> 0.0596 | AK14: =MAX(AI14-AI13,0) -> 0.0596 | AL14: 0.0184 | AM14: 0.0184 | AN14: =MAX(AL14-AL13,0) -> 0 | AO14: =MAX(AM14-AM13,0) -> 0 | AP14: 0.3348 | AQ14: 0.3348 | AR14: =MAX(AP14-AP13,0) -> 0 | AS14: =MAX(AQ14-AQ13,0) -> 0 | AT14: 0.409 | AU14: 0.409 | AV14: =MAX(AT14-AT13,0) -> 0.0367 | AW14: =MAX(AU14-AU13,0) -> 0.0367
A15: 2021 | B15: 4.9 | C15: 4.9 | D15: =MAX(B15-B14,0) -> 1.4 | E15: =MAX(C15-C14,0) -> 1.4 | F15: 21.5 | G15: 21.5 | H15: =MAX(F15-F14,0) -> 3.75 | I15: =MAX(G15-G14,0) -> 3.75 | J15: 6.87 | K15: 6.87 | L15: =MAX(J15-J14,0) -> 1.28 | M15: =MAX(K15-K14,0) -> 1.28 | N15: 7.469 | O15: 7.469 | P15: =MAX(N15-N14,0) -> 0.474 | Q15: =MAX(O15-O14,0) -> 0.474 | R15: 3.9 | S15: 3.9 | T15: =MAX(R15-R14,0) -> 1 | U15: =MAX(S15-S14,0) -> 1 | V15: 3.14 | W15: 3.14 | X15: =MAX(V15-V14,0) -> 0.847 | Y15: =MAX(W15-W14,0) -> 0.847 | Z15: 1.0769 | AA15: 1.0769 | AB15: =MAX(Z15-Z14,0) -> 0.309 | AC15: =MAX(AA15-AA14,0) -> 0.309 | AD15: 3.2922 | AE15: 3.2922 | AF15: =MAX(AD15-AD14,0) -> 0.6682 | AG15: =MAX(AE15-AE14,0) -> 0.6682 | AH15: 0.181 | AI15: 0.181 | AJ15: =MAX(AH15-AH14,0) -> 0.0983 | AK15: =MAX(AI15-AI14,0) -> 0.0983 | AL15: 0.0184 | AM15: 0.0184 | AN15: =MAX(AL15-AL14,0) -> 0 | AO15: =MAX(AM15-AM14,0) -> 0 | AP15: 0.3323 | AQ15: 0.3323 | AR15: =MAX(AP15-AP14,0) -> 0 | AS15: =MAX(AQ15-AQ14,0) -> 0 | AT15: 0.409 | AU15: 0.409 | AV15: =MAX(AT15-AT14,0) -> 0 | AW15: =MAX(AU15-AU14,0) -> 0
A16: 2022 | B16: 7.7 | C16: 7.7 | D16: =MAX(B16-B15,0) -> 2.8 | E16: =MAX(C16-C15,0) -> 2.8 | F16: 25 | G16: 25 | H16: =MAX(F16-F15,0) -> 3.5 | I16: =MAX(G16-G15,0) -> 3.5 | J16: 6.7 | K16: 6.7 | L16: =MAX(J16-J15,0) -> 0 | M16: =MAX(K16-K15,0) -> 0 | N16: 7.634 | O16: 7.634 | P16: =MAX(N16-N15,0) -> 0.165 | Q16: =MAX(O16-O15,0) -> 0.165 | R16: 5.5 | S16: 5.5 | T16: =MAX(R16-R15,0) -> 1.6 | U16: =MAX(S16-S15,0) -> 1.6 | V16: 3.824 | W16: 3.824 | X16: =MAX(V16-V15,0) -> 0.684 | Y16: =MAX(W16-W15,0) -> 0.684 | Z16: 1.1127 | AA16: 1.1127 | AB16: =MAX(Z16-Z15,0) -> 0.0358 | AC16: =MAX(AA16-AA15,0) -> 0.0358 | AD16: 3.3102 | AE16: 3.3102 | AF16: =MAX(AD16-AD15,0) -> 0.018 | AG16: =MAX(AE16-AE15,0) -> 0.018 | AH16: 0.48 | AI16: 0.48 | AJ16: =MAX(AH16-AH15,0) -> 0.299 | AK16: =MAX(AI16-AI15,0) -> 0.299 | AL16: 0.0338 | AM16: 0.0338 | AN16: =MAX(AL16-AL15,0) -> 0.0154 | AO16: =MAX(AM16-AM15,0) -> 0.0154 | AP16: 0.3322 | AQ16: 0.3322 | AR16: =MAX(AP16-AP15,0) -> 0 | AS16: =MAX(AQ16-AQ15,0) -> 0 | AT16: 0.539 | AU16: 0.539 | AV16: =MAX(AT16-AT15,0) -> 0.13 | AW16: =MAX(AU16-AU15,0) -> 0.13
... A18: 2024 | B18: 16.6 | C18: 16.6 | D18: =MAX(B18-B17,0) -> 5.6 | E18: =MAX(C18-C17,0) -> 5.6 | F18: 32 | G18: 32 | H18: =MAX(F18-F17,0) -> 3 | I18: =MAX(G18-G17,0) -> 3 | J18: 7.52 | K18: 7.52 | L18: =MAX(J18-J17,0) -> 0 | M18: =MAX(K18-K17,0) -> 0 | N18: 7.318 | O18: 7.318 | P18: =MAX(N18-N17,0) -> 0 | Q18: =MAX(O18-O17,0) -> 0 | R18: 7.6 | S18: 7.6 | T18: =MAX(R18-R17,0) -> 0.6 | U18: =MAX(S18-S17,0) -> 0.6 | V18: 4.717 | W18: 4.717 | X18: =MAX(V18-V17,0) -> 0.184 | Y18: =MAX(W18-W17,0) -> 0.184 | Z18: 1.7406 | AA18: 1.7406 | AB18: =MAX(Z18-Z17,0) -> 0.3353 | AC18: =MAX(AA18-AA17,0) -> 0.3353 | AD18: 4.3203 | AE18: 4.3203 | AF18: =MAX(AD18-AD17,0) -> 0.614 | AG18: =MAX(AE18-AE17,0) -> 0.614 | AH18: 1.3925 | AI18: 1.3925 | AJ18: =MAX(AH18-AH17,0) -> 0.6765 | AK18: =MAX(AI18-AI17,0) -> 0.6765 | AL18: 0.0338 | AM18: 0.0338 | AN18: =MAX(AL18-AL17,0) -> 0 | AO18: =MAX(AM18-AM17,0) -> 0 | AP18: 0.5277 | AQ18: 0.5277 | AR18: =MAX(AP18-AP17,0) -> 0.0805 | AS18: =MAX(AQ18-AQ17,0) -> 0.0805 | AT18: 1.1507 | AU18: 1.1507 | AV18: =MAX(AT18-AT17,0) -> 0.1357 | AW18: =MAX(AU18-AU17,0) -> 0.1357
A19: 2025 | B19: =Parameters!$D$4+(Parameters!$G$4-Parameters!$D$4)*((1/(1+EXP(-Parameters!$I$4*($A19-Parameters!$J$4))))-(1/(1+EXP(-Parameters!$I$4*(2024-Parameters!$J$4)))))/(1-(1/(1+EXP(-Parameters!$I$4*(2024-Parameters!$J$4))))) -> 18.548816 | C19: =MIN(Parameters!$D$4+IF(Parameters!$K$4=0,Parameters!$E$4*($A19-2024),Parameters!$E$4*((1+Parameters!$K$4)^($A19-2024)-1)/Parameters!$K$4),Parameters!$G$4) -> 20.44 | D19: =MAX(B19-B18,0) -> 1.9488158 | E19: =MAX(C19-C18,0) -> 3.84 | F19: =Parameters!$D$5+(Parameters!$G$5-Parameters!$D$5)*((1/(1+EXP(-Parameters!$I$5*($A19-Parameters!$J$5))))-(1/(1+EXP(-Parameters!$I$5*(2024-Parameters!$J$5)))))/(1-(1/(1+EXP(-Parameters!$I$5*(2024-Parameters!$J$5))))) -> 34.830621 | G19: =MIN(Parameters!$D$5+IF(Parameters!$K$5=0,Parameters!$E$5*($A19-2024),Parameters!$E$5*((1+Parameters!$K$5)^($A19-2024)-1)/Parameters!$K$5),Parameters!$G$5) -> 35.92 | H19: =MAX(F19-F18,0) -> 2.8306214 | I19: =MAX(G19-G18,0) -> 3.92 | J19: =Parameters!$D$6+(Parameters!$G$6-Parameters!$D$6)*((1/(1+EXP(-Parameters!$I$6*($A19-Parameters!$J$6))))-(1/(1+EXP(-Parameters!$I$6*(2024-Parameters!$J$6)))))/(1-(1/(1+EXP(-Parameters!$I$6*(2024-Parameters!$J$6))))) -> 8.1072935 | K19: =MIN(Parameters!$D$6+IF(Parameters!$K$6=0,Parameters!$E$6*($A19-2024),Parameters!$E$6*((1+Parameters!$K$6)^($A19-2024)-1)/Parameters!$K$6),Parameters!$G$6) -> 7.74 | L19: =MAX(J19-J18,0) -> 0.58729349 | M19: =MAX(K19-K18,0) -> 0.22 | N19: =Parameters!$D$7+(Parameters!$G$7-Parameters!$D$7)*((1/(1+EXP(-Parameters!$I$7*($A19-Parameters!$J$7))))-(1/(1+EXP(-Parameters!$I$7*(2024-Parameters!$J$7)))))/(1-(1/(1+EXP(-Parameters!$I$7*(2024-Parameters!$J$7))))) -> 7.8861184 | O19: =MIN(Parameters!$D$7+IF(Parameters!$K$7=0,Parameters!$E$7*($A19-2024),Parameters!$E$7*((1+Parameters!$K$7)^($A19-2024)-1)/Parameters!$K$7),Parameters!$G$7) -> 7.318 | P19: =MAX(N19-N18,0) -> 0.5681184 | Q19: =MAX(O19-O18,0) -> 0 | R19: =Parameters!$D$8+(Parameters!$G$8-Parameters!$D$8)*((1/(1+EXP(-Parameters!$I$8*($A19-Parameters!$J$8))))-(1/(1+EXP(-Parameters!$I$8*(2024-Parameters!$J$8)))))/(1-(1/(1+EXP(-Parameters!$I$8*(2024-Parameters!$J$8))))) -> 8.4739294 | S19: =MIN(Parameters!$D$8+IF(Parameters!$K$8=0,Parameters!$E$8*($A19-2024),Parameters!$E$8*((1+Parameters!$K$8)^($A19-2024)-1)/Parameters!$K$8),Parameters!$G$8) -> 8.83 | T19: =MAX(R19-R18,0) -> 0.87392939 | U19: =MAX(S19-S18,0) -> 1.23 | V19: =Parameters!$D$9+(Parameters!$G$9-Parameters!$D$9)*((1/(1+EXP(-Parameters!$I$9*($A19-Parameters!$J$9))))-(1/(1+EXP(-Parameters!$I$9*(2024-Parameters!$J$9)))))/(1-(1/(1+EXP(-Parameters!$I$9*(2024-Parameters!$J$9))))) -> 5.344957 | W19: =MIN(Parameters!$D$9+IF(Parameters!$K$9=0,Parameters!$E$9*($A19-2024),Parameters!$E$9*((1+Parameters!$K$9)^($A19-2024)-1)/Parameters!$K$9),Parameters!$G$9) -> 5.243 | X19: =MAX(V19-V18,0) -> 0.62795703 | Y19: =MAX(W19-W18,0) -> 0.526 | Z19: =Parameters!$D$10+(Parameters!$G$10-Parameters!$D$10)*((1/(1+EXP(-Parameters!$I$10*($A19-Parameters!$J$10))))-(1/(1+EXP(-Parameters!$I$10*(2024-Parameters!$J$10)))))/(1-(1/(1+EXP(-Parameters!$I$10*(2024-Parameters!$J$10))))) -> 1.9153497 | AA19: =MIN(Parameters!$D$10+IF(Parameters!$K$10=0,Parameters!$E$10*($A19-2024),Parameters!$E$10*((1+Parameters!$K$10)^($A19-2024)-1)/Parameters!$K$10),Parameters!$G$10) -> 1.9616 | AB19: =MAX(Z19-Z18,0) -> 0.17474974 | AC19: =MAX(AA19-AA18,0) -> 0.221 | AD19: =Parameters!$D$11+(Parameters!$G$11-Parameters!$D$11)*((1/(1+EXP(-Parameters!$I$11*($A19-Parameters!$J$11))))-(1/(1+EXP(-Parameters!$I$11*(2024-Parameters!$J$11)))))/(1-(1/(1+EXP(-Parameters!$I$11*(2024-Parameters!$J$11))))) -> 4.7691294 | AE19: =MIN(Parameters!$D$11+IF(Parameters!$K$11=0,Parameters!$E$11*($A19-2024),Parameters!$E$11*((1+Parameters!$K$11)^($A19-2024)-1)/Parameters!$K$11),Parameters!$G$11) -> 4.6633 | AF19: =MAX(AD19-AD18,0) -> 0.44882939 | AG19: =MAX(AE19-AE18,0) -> 0.343 | AH19: =Parameters!$D$12+(Parameters!$G$12-Parameters!$D$12)*((1/(1+EXP(-Parameters!$I$12*($A19-Parameters!$J$12))))-(1/(1+EXP(-Parameters!$I$12*(2024-Parameters!$J$12)))))/(1-(1/(1+EXP(-Parameters!$I$12*(2024-Parameters!$J$12))))) -> 1.8736087 | AI19: =MIN(Parameters!$D$12+IF(Parameters!$K$12=0,Parameters!$E$12*($A19-2024),Parameters!$E$12*((1+Parameters!$K$12)^($A19-2024)-1)/Parameters!$K$12),Parameters!$G$12) -> 1.7965 | AJ19: =MAX(AH19-AH18,0) -> 0.48110873 | AK19: =MAX(AI19-AI18,0) -> 0.404 | AL19: =Parameters!$D$13+(Parameters!$G$13-Parameters!$D$13)*((1/(1+EXP(-Parameters!$I$13*($A19-Parameters!$J$13))))-(1/(1+EXP(-Parameters!$I$13*(2024-Parameters!$J$13)))))/(1-(1/(1+EXP(-Parameters!$I$13*(2024-Parameters!$J$13))))) -> 0.20069754 | AM19: =MIN(Parameters!$D$13+IF(Parameters!$K$13=0,Parameters!$E$13*($A19-2024),Parameters!$E$13*((1+Parameters!$K$13)^($A19-2024)-1)/Parameters!$K$13),Parameters!$G$13) -> 0.0388 | AN19: =MAX(AL19-AL18,0) -> 0.16689754 | AO19: =MAX(AM19-AM18,0) -> 0.005 | AP19: =Parameters!$D$14+(Parameters!$G$14-Parameters!$D$14)*((1/(1+EXP(-Parameters!$I$14*($A19-Parameters!$J$14))))-(1/(1+EXP(-Parameters!$I$14*(2024-Parameters!$J$14)))))/(1-(1/(1+EXP(-Parameters!$I$14*(2024-Parameters!$J$14))))) -> 0.65497669 | AQ19: =MIN(Parameters!$D$14+IF(Parameters!$K$14=0,Parameters!$E$14*($A19-2024),Parameters!$E$14*((1+Parameters!$K$14)^($A19-2024)-1)/Parameters!$K$14),Parameters!$G$14) -> 0.5927 | AR19: =MAX(AP19-AP18,0) -> 0.12727669 | AS19: =MAX(AQ19-AQ18,0) -> 0.065 | AT19: =Parameters!$D$15+(Parameters!$G$15-Parameters!$D$15)*((1/(1+EXP(-Parameters!$I$15*($A19-Parameters!$J$15))))-(1/(1+EXP(-Parameters!$I$15*(2024-Parameters!$J$15)))))/(1-(1/(1+EXP(-Parameters!$I$15*(2024-Parameters!$J$15))))) -> 1.2559485 | AU19: =MIN(Parameters!$D$15+IF(Parameters!$K$15=0,Parameters!$E$15*($A19-2024),Parameters!$E$15*((1+Parameters!$K$15)^($A19-2024)-1)/Parameters!$K$15),Parameters!$G$15) -> 1.3977 | AV19: =MAX(AT19-AT18,0) -> 0.10524855 | AW19: =MAX(AU19-AU18,0) -> 0.247
A20: 2026 | B20: =Parameters!$D$4+(Parameters!$G$4-Parameters!$D$4)*((1/(1+EXP(-Parameters!$I$4*($A20-Parameters!$J$4))))-(1/(1+EXP(-Parameters!$I$4*(2024-Parameters!$J$4)))))/(1-(1/(1+EXP(-Parameters!$I$4*(2024-Parameters!$J$4))))) -> 20.765442 | C20: =MIN(Parameters!$D$4+IF(Parameters!$K$4=0,Parameters!$E$4*($A20-2024),Parameters!$E$4*((1+Parameters!$K$4)^($A20-2024)-1)/Parameters!$K$4),Parameters!$G$4) -> 24.5104 | D20: =MAX(B20-B19,0) -> 2.2166258 | E20: =MAX(C20-C19,0) -> 4.0704 | F20: =Parameters!$D$5+(Parameters!$G$5-Parameters!$D$5)*((1/(1+EXP(-Parameters!$I$5*($A20-Parameters!$J$5))))-(1/(1+EXP(-Parameters!$I$5*(2024-Parameters!$J$5)))))/(1-(1/(1+EXP(-Parameters!$I$5*(2024-Parameters!$J$5))))) -> 37.928598 | G20: =MIN(Parameters!$D$5+IF(Parameters!$K$5=0,Parameters!$E$5*($A20-2024),Parameters!$E$5*((1+Parameters!$K$5)^($A20-2024)-1)/Parameters!$K$5),Parameters!$G$5) -> 40.036 | H20: =MAX(F20-F19,0) -> 3.0979762 | I20: =MAX(G20-G19,0) -> 4.116 | J20: =Parameters!$D$6+(Parameters!$G$6-Parameters!$D$6)*((1/(1+EXP(-Parameters!$I$6*($A20-Parameters!$J$6))))-(1/(1+EXP(-Parameters!$I$6*(2024-Parameters!$J$6)))))/(1-(1/(1+EXP(-Parameters!$I$6*(2024-Parameters!$J$6))))) -> 8.7964255 | K20: =MIN(Parameters!$D$6+IF(Parameters!$K$6=0,Parameters!$E$6*($A20-2024),Parameters!$E$6*((1+Parameters!$K$6)^($A20-2024)-1)/Parameters!$K$6),Parameters!$G$6) -> 7.9776 | L20: =MAX(J20-J19,0) -> 0.68913199 | M20: =MAX(K20-K19,0) -> 0.2376 | N20: =Parameters!$D$7+(Parameters!$G$7-Parameters!$D$7)*((1/(1+EXP(-Parameters!$I$7*($A20-Parameters!$J$7))))-(1/(1+EXP(-Parameters!$I$7*(2024-Parameters!$J$7)))))/(1-(1/(1+EXP(-Parameters!$I$7*(2024-Parameters!$J$7))))) -> 8.5572003 | O20: =MIN(Parameters!$D$7+IF(Parameters!$K$7=0,Parameters!$E$7*($A20-2024),Parameters!$E$7*((1+Parameters!$K$7)^($A20-2024)-1)/Parameters!$K$7),Parameters!$G$7) -> 7.318 | P20: =MAX(N20-N19,0) -> 0.67108193 | Q20: =MAX(O20-O19,0) -> 0 | R20: =Parameters!$D$8+(Parameters!$G$8-Parameters!$D$8)*((1/(1+EXP(-Parameters!$I$8*($A20-Parameters!$J$8))))-(1/(1+EXP(-Parameters!$I$8*(2024-Parameters!$J$8)))))/(1-(1/(1+EXP(-Parameters!$I$8*(2024-Parameters!$J$8))))) -> 9.4679558 | S20: =MIN(Parameters!$D$8+IF(Parameters!$K$8=0,Parameters!$E$8*($A20-2024),Parameters!$E$8*((1+Parameters!$K$8)^($A20-2024)-1)/Parameters!$K$8),Parameters!$G$8) -> 10.1338 | T20: =MAX(R20-R19,0) -> 0.99402645 | U20: =MAX(S20-S19,0) -> 1.3038 | V20: =Parameters!$D$9+(Parameters!$G$9-Parameters!$D$9)*((1/(1+EXP(-Parameters!$I$9*($A20-Parameters!$J$9))))-(1/(1+EXP(-Parameters!$I$9*(2024-Parameters!$J$9)))))/(1-(1/(1+EXP(-Parameters!$I$9*(2024-Parameters!$J$9))))) -> 6.0432167 | W20: =MIN(Parameters!$D$9+IF(Parameters!$K$9=0,Parameters!$E$9*($A20-2024),Parameters!$E$9*((1+Parameters!$K$9)^($A20-2024)-1)/Parameters!$K$9),Parameters!$G$9) -> 5.80056 | X20: =MAX(V20-V19,0) -> 0.69825965 | Y20: =MAX(W20-W19,0) -> 0.55756 | Z20: =Parameters!$D$10+(Parameters!$G$10-Parameters!$D$10)*((1/(1+EXP(-Parameters!$I$10*($A20-Parameters!$J$10))))-(1/(1+EXP(-Parameters!$I$10*(2024-Parameters!$J$10)))))/(1-(1/(1+EXP(-Parameters!$I$10*(2024-Parameters!$J$10))))) -> 2.1168897 | AA20: =MIN(Parameters!$D$10+IF(Parameters!$K$10=0,Parameters!$E$10*($A20-2024),Parameters!$E$10*((1+Parameters!$K$10)^($A20-2024)-1)/Parameters!$K$10),Parameters!$G$10) -> 2.19807 | AB20: =MAX(Z20-Z19,0) -> 0.20153999 | AC20: =MAX(AA20-AA19,0) -> 0.23647 | AD20: =Parameters!$D$11+(Parameters!$G$11-Parameters!$D$11)*((1/(1+EXP(-Parameters!$I$11*($A20-Parameters!$J$11))))-(1/(1+EXP(-Parameters!$I$11*(2024-Parameters!$J$11)))))/(1-(1/(1+EXP(-Parameters!$I$11*(2024-Parameters!$J$11))))) -> 5.271606 | AE20: =MIN(Parameters!$D$11+IF(Parameters!$K$11=0,Parameters!$E$11*($A20-2024),Parameters!$E$11*((1+Parameters!$K$11)^($A20-2024)-1)/Parameters!$K$11),Parameters!$G$11) -> 5.02688 | AF20: =MAX(AD20-AD19,0) -> 0.50247666 | AG20: =MAX(AE20-AE19,0) -> 0.36358 | AH20: =Parameters!$D$12+(Parameters!$G$12-Parameters!$D$12)*((1/(1+EXP(-Parameters!$I$12*($A20-Parameters!$J$12))))-(1/(1+EXP(-Parameters!$I$12*(2024-Parameters!$J$12)))))/(1-(1/(1+EXP(-Parameters!$I$12*(2024-Parameters!$J$12))))) -> 2.4381432 | AI20: =MIN(Parameters!$D$12+IF(Parameters!$K$12=0,Parameters!$E$12*($A20-2024),Parameters!$E$12*((1+Parameters!$K$12)^($A20-2024)-1)/Parameters!$K$12),Parameters!$G$12) -> 2.2409 | AJ20: =MAX(AH20-AH19,0) -> 0.56453446 | AK20: =MAX(AI20-AI19,0) -> 0.4444 | AL20: =Parameters!$D$13+(Parameters!$G$13-Parameters!$D$13)*((1/(1+EXP(-Parameters!$I$13*($A20-Parameters!$J$13))))-(1/(1+EXP(-Parameters!$I$13*(2024-Parameters!$J$13)))))/(1-(1/(1+EXP(-Parameters!$I$13*(2024-Parameters!$J$13))))) -> 0.39779798 | AM20: =MIN(Parameters!$D$13+IF(Parameters!$K$13=0,Parameters!$E$13*($A20-2024),Parameters!$E$13*((1+Parameters!$K$13)^($A20-2024)-1)/Parameters!$K$13),Parameters!$G$13) -> 0.0443 | AN20: =MAX(AL20-AL19,0) -> 0.19710044 | AO20: =MAX(AM20-AM19,0) -> 0.0055 | AP20: =Parameters!$D$14+(Parameters!$G$14-Parameters!$D$14)*((1/(1+EXP(-Parameters!$I$14*($A20-Parameters!$J$14))))-(1/(1+EXP(-Parameters!$I$14*(2024-Parameters!$J$14)))))/(1-(1/(1+EXP(-Parameters!$I$14*(2024-Parameters!$J$14))))) -> 0.80176571 | AQ20: =MIN(Parameters!$D$14+IF(Parameters!$K$14=0,Parameters!$E$14*($A20-2024),Parameters!$E$14*((1+Parameters!$K$14)^($A20-2024)-1)/Parameters!$K$14),Parameters!$G$14) -> 0.6642 | AR20: =MAX(AP20-AP19,0) -> 0.14678902 | AS20: =MAX(AQ20-AQ19,0) -> 0.0715 | AT20: =Parameters!$D$15+(Parameters!$G$15-Parameters!$D$15)*((1/(1+EXP(-Parameters!$I$15*($A20-Parameters!$J$15))))-(1/(1+EXP(-Parameters!$I$15*(2024-Parameters!$J$15)))))/(1-(1/(1+EXP(-Parameters!$I$15*(2024-Parameters!$J$15))))) -> 1.3737771 | AU20: =MIN(Parameters!$D$15+IF(Parameters!$K$15=0,Parameters!$E$15*($A20-2024),Parameters!$E$15*((1+Parameters!$K$15)^($A20-2024)-1)/Parameters!$K$15),Parameters!$G$15) -> 1.66446 | AV20: =MAX(AT20-AT19,0) -> 0.1178286 | AW20: =MAX(AU20-AU19,0) -> 0.26676
A21: 2027 | B21: =Parameters!$D$4+(Parameters!$G$4-Parameters!$D$4)*((1/(1+EXP(-Parameters!$I$4*($A21-Parameters!$J$4))))-(1/(1+EXP(-Parameters!$I$4*(2024-Parameters!$J$4)))))/(1-(1/(1+EXP(-Parameters!$I$4*(2024-Parameters!$J$4))))) -> 23.265547 | C21: =MIN(Parameters!$D$4+IF(Parameters!$K$4=0,Parameters!$E$4*($A21-2024),Parameters!$E$4*((1+Parameters!$K$4)^($A21-2024)-1)/Parameters!$K$4),Parameters!$G$4) -> 28.825024 | D21: =MAX(B21-B20,0) -> 2.5001058 | E21: =MAX(C21-C20,0) -> 4.314624 | F21: =Parameters!$D$5+(Parameters!$G$5-Parameters!$D$5)*((1/(1+EXP(-Parameters!$I$5*($A21-Parameters!$J$5))))-(1/(1+EXP(-Parameters!$I$5*(2024-Parameters!$J$5)))))/(1-(1/(1+EXP(-Parameters!$I$5*(2024-Parameters!$J$5))))) -> 41.28845 | G21: =MIN(Parameters!$D$5+IF(Parameters!$K$5=0,Parameters!$E$5*($A21-2024),Parameters!$E$5*((1+Parameters!$K$5)^($A21-2024)-1)/Parameters!$K$5),Parameters!$G$5) -> 44.3578 | H21: =MAX(F21-F20,0) -> 3.3598523 | I21: =MAX(G21-G20,0) -> 4.3218 | J21: =Parameters!$D$6+(Parameters!$G$6-Parameters!$D$6)*((1/(1+EXP(-Parameters!$I$6*($A21-Parameters!$J$6))))-(1/(1+EXP(-Parameters!$I$6*(2024-Parameters!$J$6)))))/(1-(1/(1+EXP(-Parameters!$I$6*(2024-Parameters!$J$6))))) -> 9.5987703 | K21: =MIN(Parameters!$D$6+IF(Parameters!$K$6=0,Parameters!$E$6*($A21-2024),Parameters!$E$6*((1+Parameters!$K$6)^($A21-2024)-1)/Parameters!$K$6),Parameters!$G$6) -> 8.234208 | L21: =MAX(J21-J20,0) -> 0.80234487 | M21: =MAX(K21-K20,0) -> 0.256608 | N21: =Parameters!$D$7+(Parameters!$G$7-Parameters!$D$7)*((1/(1+EXP(-Parameters!$I$7*($A21-Parameters!$J$7))))-(1/(1+EXP(-Parameters!$I$7*(2024-Parameters!$J$7)))))/(1-(1/(1+EXP(-Parameters!$I$7*(2024-Parameters!$J$7))))) -> 9.3446499 | O21: =MIN(Parameters!$D$7+IF(Parameters!$K$7=0,Parameters!$E$7*($A21-2024),Parameters!$E$7*((1+Parameters!$K$7)^($A21-2024)-1)/Parameters!$K$7),Parameters!$G$7) -> 7.318 | P21: =MAX(N21-N20,0) -> 0.7874496 | Q21: =MAX(O21-O20,0) -> 0 | R21: =Parameters!$D$8+(Parameters!$G$8-Parameters!$D$8)*((1/(1+EXP(-Parameters!$I$8*($A21-Parameters!$J$8))))-(1/(1+EXP(-Parameters!$I$8*(2024-Parameters!$J$8)))))/(1-(1/(1+EXP(-Parameters!$I$8*(2024-Parameters!$J$8))))) -> 10.589106 | S21: =MIN(Parameters!$D$8+IF(Parameters!$K$8=0,Parameters!$E$8*($A21-2024),Parameters!$E$8*((1+Parameters!$K$8)^($A21-2024)-1)/Parameters!$K$8),Parameters!$G$8) -> 11.515828 | T21: =MAX(R21-R20,0) -> 1.1211506 | U21: =MAX(S21-S20,0) -> 1.382028 | V21: =Parameters!$D$9+(Parameters!$G$9-Parameters!$D$9)*((1/(1+EXP(-Parameters!$I$9*($A21-Parameters!$J$9))))-(1/(1+EXP(-Parameters!$I$9*(2024-Parameters!$J$9)))))/(1-(1/(1+EXP(-Parameters!$I$9*(2024-Parameters!$J$9))))) -> 6.8138142 | W21: =MIN(Parameters!$D$9+IF(Parameters!$K$9=0,Parameters!$E$9*($A21-2024),Parameters!$E$9*((1+Parameters!$K$9)^($A21-2024)-1)/Parameters!$K$9),Parameters!$G$9) -> 6.3915736 | X21: =MAX(V21-V20,0) -> 0.77059753 | Y21: =MAX(W21-W20,0) -> 0.5910136 | Z21: =Parameters!$D$10+(Parameters!$G$10-Parameters!$D$10)*((1/(1+EXP(-Parameters!$I$10*($A21-Parameters!$J$10))))-(1/(1+EXP(-Parameters!$I$10*(2024-Parameters!$J$10)))))/(1-(1/(1+EXP(-Parameters!$I$10*(2024-Parameters!$J$10))))) -> 2.3478293 | AA21: =MIN(Parameters!$D$10+IF(Parameters!$K$10=0,Parameters!$E$10*($A21-2024),Parameters!$E$10*((1+Parameters!$K$10)^($A21-2024)-1)/Parameters!$K$10),Parameters!$G$10) -> 2.4510929 | AB21: =MAX(Z21-Z20,0) -> 0.23093959 | AC21: =MAX(AA21-AA20,0) -> 0.2530229 | AD21: =Parameters!$D$11+(Parameters!$G$11-Parameters!$D$11)*((1/(1+EXP(-Parameters!$I$11*($A21-Parameters!$J$11))))-(1/(1+EXP(-Parameters!$I$11*(2024-Parameters!$J$11)))))/(1-(1/(1+EXP(-Parameters!$I$11*(2024-Parameters!$J$11))))) -> 5.8303372 | AE21: =MIN(Parameters!$D$11+IF(Parameters!$K$11=0,Parameters!$E$11*($A21-2024),Parameters!$E$11*((1+Parameters!$K$11)^($A21-2024)-1)/Parameters!$K$11),Parameters!$G$11) -> 5.4122748 | AF21: =MAX(AD21-AD20,0) -> 0.55873119 | AG21: =MAX(AE21-AE20,0) -> 0.3853948 | AH21: =Parameters!$D$12+(Parameters!$G$12-Parameters!$D$12)*((1/(1+EXP(-Parameters!$I$12*($A21-Parameters!$J$12))))-(1/(1+EXP(-Parameters!$I$12*(2024-Parameters!$J$12)))))/(1-(1/(1+EXP(-Parameters!$I$12*(2024-Parameters!$J$12))))) -> 3.0954212 | AI21: =MIN(Parameters!$D$12+IF(Parameters!$K$12=0,Parameters!$E$12*($A21-2024),Parameters!$E$12*((1+Parameters!$K$12)^($A21-2024)-1)/Parameters!$K$12),Parameters!$G$12) -> 2.72974 | AJ21: =MAX(AH21-AH20,0) -> 0.65727805 | AK21: =MAX(AI21-AI20,0) -> 0.48884 | AL21: =Parameters!$D$13+(Parameters!$G$13-Parameters!$D$13)*((1/(1+EXP(-Parameters!$I$13*($A21-Parameters!$J$13))))-(1/(1+EXP(-Parameters!$I$13*(2024-Parameters!$J$13)))))/(1-(1/(1+EXP(-Parameters!$I$13*(2024-Parameters!$J$13))))) -> 0.62796658 | AM21: =MIN(Parameters!$D$13+IF(Parameters!$K$13=0,Parameters!$E$13*($A21-2024),Parameters!$E$13*((1+Parameters!$K$13)^($A21-2024)-1)/Parameters!$K$13),Parameters!$G$13) -> 0.05035 | AN21: =MAX(AL21-AL20,0) -> 0.2301686 | AO21: =MAX(AM21-AM20,0) -> 0.00605 | AP21: =Parameters!$D$14+(Parameters!$G$14-Parameters!$D$14)*((1/(1+EXP(-Parameters!$I$14*($A21-Parameters!$J$14))))-(1/(1+EXP(-Parameters!$I$14*(2024-Parameters!$J$14)))))/(1-(1/(1+EXP(-Parameters!$I$14*(2024-Parameters!$J$14))))) -> 0.96996754 | AQ21: =MIN(Parameters!$D$14+IF(Parameters!$K$14=0,Parameters!$E$14*($A21-2024),Parameters!$E$14*((1+Parameters!$K$14)^($A21-2024)-1)/Parameters!$K$14),Parameters!$G$14) -> 0.74285 | AR21: =MAX(AP21-AP20,0) -> 0.16820183 | AS21: =MAX(AQ21-AQ20,0) -> 0.07865 | AT21: =Parameters!$D$15+(Parameters!$G$15-Parameters!$D$15)*((1/(1+EXP(-Parameters!$I$15*($A21-Parameters!$J$15))))-(1/(1+EXP(-Parameters!$I$15*(2024-Parameters!$J$15)))))/(1-(1/(1+EXP(-Parameters!$I$15*(2024-Parameters!$J$15))))) -> 1.5047972 | AU21: =MIN(Parameters!$D$15+IF(Parameters!$K$15=0,Parameters!$E$15*($A21-2024),Parameters!$E$15*((1+Parameters!$K$15)^($A21-2024)-1)/Parameters!$K$15),Parameters!$G$15) -> 1.9525608 | AV21: =MAX(AT21-AT20,0) -> 0.13102004 | AW21: =MAX(AU21-AU20,0) -> 0.2881008
A22: 2028 | B22: =Parameters!$D$4+(Parameters!$G$4-Parameters!$D$4)*((1/(1+EXP(-Parameters!$I$4*($A22-Parameters!$J$4))))-(1/(1+EXP(-Parameters!$I$4*(2024-Parameters!$J$4)))))/(1-(1/(1+EXP(-Parameters!$I$4*(2024-Parameters!$J$4))))) -> 26.058757 | C22: =MIN(Parameters!$D$4+IF(Parameters!$K$4=0,Parameters!$E$4*($A22-2024),Parameters!$E$4*((1+Parameters!$K$4)^($A22-2024)-1)/Parameters!$K$4),Parameters!$G$4) -> 33.398525 | D22: =MAX(B22-B21,0) -> 2.7932095 | E22: =MAX(C22-C21,0) -> 4.5735014 | F22: =Parameters!$D$5+(Parameters!$G$5-Parameters!$D$5)*((1/(1+EXP(-Parameters!$I$5*($A22-Parameters!$J$5))))-(1/(1+EXP(-Parameters!$I$5*(2024-Parameters!$J$5)))))/(1-(1/(1+EXP(-Parameters!$I$5*(2024-Parameters!$J$5))))) -> 44.896524 | G22: =MIN(Parameters!$D$5+IF(Parameters!$K$5=0,Parameters!$E$5*($A22-2024),Parameters!$E$5*((1+Parameters!$K$5)^($A22-2024)-1)/Parameters!$K$5),Parameters!$G$5) -> 48.89569 | H22: =MAX(F22-F21,0) -> 3.6080744 | I22: =MAX(G22-G21,0) -> 4.53789 | J22: =Parameters!$D$6+(Parameters!$G$6-Parameters!$D$6)*((1/(1+EXP(-Parameters!$I$6*($A22-Parameters!$J$6))))-(1/(1+EXP(-Parameters!$I$6*(2024-Parameters!$J$6)))))/(1-(1/(1+EXP(-Parameters!$I$6*(2024-Parameters!$J$6))))) -> 10.524485 | K22: =MIN(Parameters!$D$6+IF(Parameters!$K$6=0,Parameters!$E$6*($A22-2024),Parameters!$E$6*((1+Parameters!$K$6)^($A22-2024)-1)/Parameters!$K$6),Parameters!$G$6) -> 8.5113446 | L22: =MAX(J22-J21,0) -> 0.92571443 | M22: =MAX(K22-K21,0) -> 0.27713664 | N22: =Parameters!$D$7+(Parameters!$G$7-Parameters!$D$7)*((1/(1+EXP(-Parameters!$I$7*($A22-Parameters!$J$7))))-(1/(1+EXP(-Parameters!$I$7*(2024-Parameters!$J$7)))))/(1-(1/(1+EXP(-Parameters!$I$7*(2024-Parameters!$J$7))))) -> 10.261464 | O22: =MIN(Parameters!$D$7+IF(Parameters!$K$7=0,Parameters!$E$7*($A22-2024),Parameters!$E$7*((1+Parameters!$K$7)^($A22-2024)-1)/Parameters!$K$7),Parameters!$G$7) -> 7.318 | P22: =MAX(N22-N21,0) -> 0.91681442 | Q22: =MAX(O22-O21,0) -> 0 | R22: =Parameters!$D$8+(Parameters!$G$8-Parameters!$D$8)*((1/(1+EXP(-Parameters!$I$8*($A22-Parameters!$J$8))))-(1/(1+EXP(-Parameters!$I$8*(2024-Parameters!$J$8)))))/(1-(1/(1+EXP(-Parameters!$I$8*(2024-Parameters!$J$8))))) -> 11.841697 | S22: =MIN(Parameters!$D$8+IF(Parameters!$K$8=0,Parameters!$E$8*($A22-2024),Parameters!$E$8*((1+Parameters!$K$8)^($A22-2024)-1)/Parameters!$K$8),Parameters!$G$8) -> 12.980778 | T22: =MAX(R22-R21,0) -> 1.2525903 | U22: =MAX(S22-S21,0) -> 1.4649497 | V22: =Parameters!$D$9+(Parameters!$G$9-Parameters!$D$9)*((1/(1+EXP(-Parameters!$I$9*($A22-Parameters!$J$9))))-(1/(1+EXP(-Parameters!$I$9*(2024-Parameters!$J$9)))))/(1-(1/(1+EXP(-Parameters!$I$9*(2024-Parameters!$J$9))))) -> 7.6571954 | W22: =MIN(Parameters!$D$9+IF(Parameters!$K$9=0,Parameters!$E$9*($A22-2024),Parameters!$E$9*((1+Parameters!$K$9)^($A22-2024)-1)/Parameters!$K$9),Parameters!$G$9) -> 7.018048 | X22: =MAX(V22-V21,0) -> 0.84338119 | Y22: =MAX(W22-W21,0) -> 0.62647442 | Z22: =Parameters!$D$10+(Parameters!$G$10-Parameters!$D$10)*((1/(1+EXP(-Parameters!$I$10*($A22-Parameters!$J$10))))-(1/(1+EXP(-Parameters!$I$10*(2024-Parameters!$J$10)))))/(1-(1/(1+EXP(-Parameters!$I$10*(2024-Parameters!$J$10))))) -> 2.6105051 | AA22: =MIN(Parameters!$D$10+IF(Parameters!$K$10=0,Parameters!$E$10*($A22-2024),Parameters!$E$10*((1+Parameters!$K$10)^($A22-2024)-1)/Parameters!$K$10),Parameters!$G$10) -> 2.7218274 | AB22: =MAX(Z22-Z21,0) -> 0.26267575 | AC22: =MAX(AA22-AA21,0) -> 0.2707345 | AD22: =Parameters!$D$11+(Parameters!$G$11-Parameters!$D$11)*((1/(1+EXP(-Parameters!$I$11*($A22-Parameters!$J$11))))-(1/(1+EXP(-Parameters!$I$11*(2024-Parameters!$J$11)))))/(1-(1/(1+EXP(-Parameters!$I$11*(2024-Parameters!$J$11))))) -> 6.4469515 | AE22: =MIN(Parameters!$D$11+IF(Parameters!$K$11=0,Parameters!$E$11*($A22-2024),Parameters!$E$11*((1+Parameters!$K$11)^($A22-2024)-1)/Parameters!$K$11),Parameters!$G$11) -> 5.8207933 | AF22: =MAX(AD22-AD21,0) -> 0.61661428 | AG22: =MAX(AE22-AE21,0) -> 0.40851849 | AH22: =Parameters!$D$12+(Parameters!$G$12-Parameters!$D$12)*((1/(1+EXP(-Parameters!$I$12*($A22-Parameters!$J$12))))-(1/(1+EXP(-Parameters!$I$12*(2024-Parameters!$J$12)))))/(1-(1/(1+EXP(-Parameters!$I$12*(2024-Parameters!$J$12))))) -> 3.8537632 | AI22: =MIN(Parameters!$D$12+IF(Parameters!$K$12=0,Parameters!$E$12*($A22-2024),Parameters!$E$12*((1+Parameters!$K$12)^($A22-2024)-1)/Parameters!$K$12),Parameters!$G$12) -> 3.267464 | AJ22: =MAX(AH22-AH21,0) -> 0.75834195 | AK22: =MAX(AI22-AI21,0) -> 0.537724 | AL22: =Parameters!$D$13+(Parameters!$G$13-Parameters!$D$13)*((1/(1+EXP(-Parameters!$I$13*($A22-Parameters!$J$13))))-(1/(1+EXP(-Parameters!$I$13*(2024-Parameters!$J$13)))))/(1-(1/(1+EXP(-Parameters!$I$13*(2024-Parameters!$J$13))))) -> 0.89325122 | AM22: =MIN(Parameters!$D$13+IF(Parameters!$K$13=0,Parameters!$E$13*($A22-2024),Parameters!$E$13*((1+Parameters!$K$13)^($A22-2024)-1)/Parameters!$K$13),Parameters!$G$13) -> 0.057005 | AN22: =MAX(AL22-AL21,0) -> 0.26528464 | AO22: =MAX(AM22-AM21,0) -> 0.006655 | AP22: =Parameters!$D$14+(Parameters!$G$14-Parameters!$D$14)*((1/(1+EXP(-Parameters!$I$14*($A22-Parameters!$J$14))))-(1/(1+EXP(-Parameters!$I$14*(2024-Parameters!$J$14)))))/(1-(1/(1+EXP(-Parameters!$I$14*(2024-Parameters!$J$14))))) -> 1.161284 | AQ22: =MIN(Parameters!$D$14+IF(Parameters!$K$14=0,Parameters!$E$14*($A22-2024),Parameters!$E$14*((1+Parameters!$K$14)^($A22-2024)-1)/Parameters!$K$14),Parameters!$G$14) -> 0.829365 | AR22: =MAX(AP22-AP21,0) -> 0.19131645 | AS22: =MAX(AQ22-AQ21,0) -> 0.086515 | AT22: =Parameters!$D$15+(Parameters!$G$15-Parameters!$D$15)*((1/(1+EXP(-Parameters!$I$15*($A22-Parameters!$J$15))))-(1/(1+EXP(-Parameters!$I$15*(2024-Parameters!$J$15)))))/(1-(1/(1+EXP(-Parameters!$I$15*(2024-Parameters!$J$15))))) -> 1.6493906 | AU22: =MIN(Parameters!$D$15+IF(Parameters!$K$15=0,Parameters!$E$15*($A22-2024),Parameters!$E$15*((1+Parameters!$K$15)^($A22-2024)-1)/Parameters!$K$15),Parameters!$G$15) -> 2.2637097 | AV22: =MAX(AT22-AT21,0) -> 0.14459338 | AW22: =MAX(AU22-AU21,0) -> 0.31114886
A23: 2029 | B23: =Parameters!$D$4+(Parameters!$G$4-Parameters!$D$4)*((1/(1+EXP(-Parameters!$I$4*($A23-Parameters!$J$4))))-(1/(1+EXP(-Parameters!$I$4*(2024-Parameters!$J$4)))))/(1-(1/(1+EXP(-Parameters!$I$4*(2024-Parameters!$J$4))))) -> 29.146543 | C23: =MIN(Parameters!$D$4+IF(Parameters!$K$4=0,Parameters!$E$4*($A23-2024),Parameters!$E$4*((1+Parameters!$K$4)^($A23-2024)-1)/Parameters!$K$4),Parameters!$G$4) -> 38.246437 | D23: =MAX(B23-B22,0) -> 3.0877858 | E23: =MAX(C23-C22,0) -> 4.8479115 | F23: =Parameters!$D$5+(Parameters!$G$5-Parameters!$D$5)*((1/(1+EXP(-Parameters!$I$5*($A23-Parameters!$J$5))))-(1/(1+EXP(-Parameters!$I$5*(2024-Parameters!$J$5)))))/(1-(1/(1+EXP(-Parameters!$I$5*(2024-Parameters!$J$5))))) -> 48.73032 | G23: =MIN(Parameters!$D$5+IF(Parameters!$K$5=0,Parameters!$E$5*($A23-2024),Parameters!$E$5*((1+Parameters!$K$5)^($A23-2024)-1)/Parameters!$K$5),Parameters!$G$5) -> 53.660475 | H23: =MAX(F23-F22,0) -> 3.8337955 | I23: =MAX(G23-G22,0) -> 4.7647845 | J23: =Parameters!$D$6+(Parameters!$G$6-Parameters!$D$6)*((1/(1+EXP(-Parameters!$I$6*($A23-Parameters!$J$6))))-(1/(1+EXP(-Parameters!$I$6*(2024-Parameters!$J$6)))))/(1-(1/(1+EXP(-Parameters!$I$6*(2024-Parameters!$J$6))))) -> 11.581417 | K23: =MIN(Parameters!$D$6+IF(Parameters!$K$6=0,Parameters!$E$6*($A23-2024),Parameters!$E$6*((1+Parameters!$K$6)^($A23-2024)-1)/Parameters!$K$6),Parameters!$G$6) -> 8.8106522 | L23: =MAX(J23-J22,0) -> 1.0569324 | M23: =MAX(K23-K22,0) -> 0.29930757 | N23: =Parameters!$D$7+(Parameters!$G$7-Parameters!$D$7)*((1/(1+EXP(-Parameters!$I$7*($A23-Parameters!$J$7))))-(1/(1+EXP(-Parameters!$I$7*(2024-Parameters!$J$7)))))/(1-(1/(1+EXP(-Parameters!$I$7*(2024-Parameters!$J$7))))) -> 11.319249 | O23: =MIN(Parameters!$D$7+IF(Parameters!$K$7=0,Parameters!$E$7*($A23-2024),Parameters!$E$7*((1+Parameters!$K$7)^($A23-2024)-1)/Parameters!$K$7),Parameters!$G$7) -> 7.318 | P23: =MAX(N23-N22,0) -> 1.057785 | Q23: =MAX(O23-O22,0) -> 0 | R23: =Parameters!$D$8+(Parameters!$G$8-Parameters!$D$8)*((1/(1+EXP(-Parameters!$I$8*($A23-Parameters!$J$8))))-(1/(1+EXP(-Parameters!$I$8*(2024-Parameters!$J$8)))))/(1-(1/(1+EXP(-Parameters!$I$8*(2024-Parameters!$J$8))))) -> 13.226387 | S23: =MIN(Parameters!$D$8+IF(Parameters!$K$8=0,Parameters!$E$8*($A23-2024),Parameters!$E$8*((1+Parameters!$K$8)^($A23-2024)-1)/Parameters!$K$8),Parameters!$G$8) -> 14.533624 | T23: =MAX(R23-R22,0) -> 1.3846905 | U23: =MAX(S23-S22,0) -> 1.5528467 | V23: =Parameters!$D$9+(Parameters!$G$9-Parameters!$D$9)*((1/(1+EXP(-Parameters!$I$9*($A23-Parameters!$J$9))))-(1/(1+EXP(-Parameters!$I$9*(2024-Parameters!$J$9)))))/(1-(1/(1+EXP(-Parameters!$I$9*(2024-Parameters!$J$9))))) -> 8.5718687 | W23: =MIN(Parameters!$D$9+IF(Parameters!$K$9=0,Parameters!$E$9*($A23-2024),Parameters!$E$9*((1+Parameters!$K$9)^($A23-2024)-1)/Parameters!$K$9),Parameters!$G$9) -> 7.6821109 | X23: =MAX(V23-V22,0) -> 0.91467333 | Y23: =MAX(W23-W22,0) -> 0.66406288 | Z23: =Parameters!$D$10+(Parameters!$G$10-Parameters!$D$10)*((1/(1+EXP(-Parameters!$I$10*($A23-Parameters!$J$10))))-(1/(1+EXP(-Parameters!$I$10*(2024-Parameters!$J$10)))))/(1-(1/(1+EXP(-Parameters!$I$10*(2024-Parameters!$J$10))))) -> 2.9067739 | AA23: =MIN(Parameters!$D$10+IF(Parameters!$K$10=0,Parameters!$E$10*($A23-2024),Parameters!$E$10*((1+Parameters!$K$10)^($A23-2024)-1)/Parameters!$K$10),Parameters!$G$10) -> 3.0115133 | AB23: =MAX(Z23-Z22,0) -> 0.29626884 | AC23: =MAX(AA23-AA22,0) -> 0.28968592 | AD23: =Parameters!$D$11+(Parameters!$G$11-Parameters!$D$11)*((1/(1+EXP(-Parameters!$I$11*($A23-Parameters!$J$11))))-(1/(1+EXP(-Parameters!$I$11*(2024-Parameters!$J$11)))))/(1-(1/(1+EXP(-Parameters!$I$11*(2024-Parameters!$J$11))))) -> 7.1218056 | AE23: =MIN(Parameters!$D$11+IF(Parameters!$K$11=0,Parameters!$E$11*($A23-2024),Parameters!$E$11*((1+Parameters!$K$11)^($A23-2024)-1)/Parameters!$K$11),Parameters!$G$11) -> 6.2538229 | AF23: =MAX(AD23-AD22,0) -> 0.67485408 | AG23: =MAX(AE23-AE22,0) -> 0.4330296 | AH23: =Parameters!$D$12+(Parameters!$G$12-Parameters!$D$12)*((1/(1+EXP(-Parameters!$I$12*($A23-Parameters!$J$12))))-(1/(1+EXP(-Parameters!$I$12*(2024-Parameters!$J$12)))))/(1-(1/(1+EXP(-Parameters!$I$12*(2024-Parameters!$J$12))))) -> 4.7195984 | AI23: =MIN(Parameters!$D$12+IF(Parameters!$K$12=0,Parameters!$E$12*($A23-2024),Parameters!$E$12*((1+Parameters!$K$12)^($A23-2024)-1)/Parameters!$K$12),Parameters!$G$12) -> 3.8589604 | AJ23: =MAX(AH23-AH22,0) -> 0.86583522 | AK23: =MAX(AI23-AI22,0) -> 0.5914964 | AL23: =Parameters!$D$13+(Parameters!$G$13-Parameters!$D$13)*((1/(1+EXP(-Parameters!$I$13*($A23-Parameters!$J$13))))-(1/(1+EXP(-Parameters!$I$13*(2024-Parameters!$J$13)))))/(1-(1/(1+EXP(-Parameters!$I$13*(2024-Parameters!$J$13))))) -> 1.1944296 | AM23: =MIN(Parameters!$D$13+IF(Parameters!$K$13=0,Parameters!$E$13*($A23-2024),Parameters!$E$13*((1+Parameters!$K$13)^($A23-2024)-1)/Parameters!$K$13),Parameters!$G$13) -> 0.0643255 | AN23: =MAX(AL23-AL22,0) -> 0.30117834 | AO23: =MAX(AM23-AM22,0) -> 0.0073205 | AP23: =Parameters!$D$14+(Parameters!$G$14-Parameters!$D$14)*((1/(1+EXP(-Parameters!$I$14*($A23-Parameters!$J$14))))-(1/(1+EXP(-Parameters!$I$14*(2024-Parameters!$J$14)))))/(1-(1/(1+EXP(-Parameters!$I$14*(2024-Parameters!$J$14))))) -> 1.3770675 | AQ23: =MIN(Parameters!$D$14+IF(Parameters!$K$14=0,Parameters!$E$14*($A23-2024),Parameters!$E$14*((1+Parameters!$K$14)^($A23-2024)-1)/Parameters!$K$14),Parameters!$G$14) -> 0.9245315 | AR23: =MAX(AP23-AP22,0) -> 0.21578354 | AS23: =MAX(AQ23-AQ22,0) -> 0.0951665 | AT23: =Parameters!$D$15+(Parameters!$G$15-Parameters!$D$15)*((1/(1+EXP(-Parameters!$I$15*($A23-Parameters!$J$15))))-(1/(1+EXP(-Parameters!$I$15*(2024-Parameters!$J$15)))))/(1-(1/(1+EXP(-Parameters!$I$15*(2024-Parameters!$J$15))))) -> 1.8076409 | AU23: =MIN(Parameters!$D$15+IF(Parameters!$K$15=0,Parameters!$E$15*($A23-2024),Parameters!$E$15*((1+Parameters!$K$15)^($A23-2024)-1)/Parameters!$K$15),Parameters!$G$15) -> 2.5997504 | AV23: =MAX(AT23-AT22,0) -> 0.15825036 | AW23: =MAX(AU23-AU22,0) -> 0.33604077
A24: 2030 | B24: =Parameters!$D$4+(Parameters!$G$4-Parameters!$D$4)*((1/(1+EXP(-Parameters!$I$4*($A24-Parameters!$J$4))))-(1/(1+EXP(-Parameters!$I$4*(2024-Parameters!$J$4)))))/(1-(1/(1+EXP(-Parameters!$I$4*(2024-Parameters!$J$4))))) -> 32.520246 | C24: =MIN(Parameters!$D$4+IF(Parameters!$K$4=0,Parameters!$E$4*($A24-2024),Parameters!$E$4*((1+Parameters!$K$4)^($A24-2024)-1)/Parameters!$K$4),Parameters!$G$4) -> 43.385223 | D24: =MAX(B24-B23,0) -> 3.3737035 | E24: =MAX(C24-C23,0) -> 5.1387862 | F24: =Parameters!$D$5+(Parameters!$G$5-Parameters!$D$5)*((1/(1+EXP(-Parameters!$I$5*($A24-Parameters!$J$5))))-(1/(1+EXP(-Parameters!$I$5*(2024-Parameters!$J$5)))))/(1-(1/(1+EXP(-Parameters!$I$5*(2024-Parameters!$J$5))))) -> 52.758365 | G24: =MIN(Parameters!$D$5+IF(Parameters!$K$5=0,Parameters!$E$5*($A24-2024),Parameters!$E$5*((1+Parameters!$K$5)^($A24-2024)-1)/Parameters!$K$5),Parameters!$G$5) -> 58.663498 | H24: =MAX(F24-F23,0) -> 4.0280448 | I24: =MAX(G24-G23,0) -> 5.0030237 | J24: =Parameters!$D$6+(Parameters!$G$6-Parameters!$D$6)*((1/(1+EXP(-Parameters!$I$6*($A24-Parameters!$J$6))))-(1/(1+EXP(-Parameters!$I$6*(2024-Parameters!$J$6)))))/(1-(1/(1+EXP(-Parameters!$I$6*(2024-Parameters!$J$6))))) -> 12.773842 | K24: =MIN(Parameters!$D$6+IF(Parameters!$K$6=0,Parameters!$E$6*($A24-2024),Parameters!$E$6*((1+Parameters!$K$6)^($A24-2024)-1)/Parameters!$K$6),Parameters!$G$6) -> 9.1339044 | L24: =MAX(J24-J23,0) -> 1.1924249 | M24: =MAX(K24-K23,0) -> 0.32325218 | N24: =Parameters!$D$7+(Parameters!$G$7-Parameters!$D$7)*((1/(1+EXP(-Parameters!$I$7*($A24-Parameters!$J$7))))-(1/(1+EXP(-Parameters!$I$7*(2024-Parameters!$J$7)))))/(1-(1/(1+EXP(-Parameters!$I$7*(2024-Parameters!$J$7))))) -> 12.526973 | O24: =MIN(Parameters!$D$7+IF(Parameters!$K$7=0,Parameters!$E$7*($A24-2024),Parameters!$E$7*((1+Parameters!$K$7)^($A24-2024)-1)/Parameters!$K$7),Parameters!$G$7) -> 7.318 | P24: =MAX(N24-N23,0) -> 1.2077236 | Q24: =MAX(O24-O23,0) -> 0 | R24: =Parameters!$D$8+(Parameters!$G$8-Parameters!$D$8)*((1/(1+EXP(-Parameters!$I$8*($A24-Parameters!$J$8))))-(1/(1+EXP(-Parameters!$I$8*(2024-Parameters!$J$8)))))/(1-(1/(1+EXP(-Parameters!$I$8*(2024-Parameters!$J$8))))) -> 14.739295 | S24: =MIN(Parameters!$D$8+IF(Parameters!$K$8=0,Parameters!$E$8*($A24-2024),Parameters!$E$8*((1+Parameters!$K$8)^($A24-2024)-1)/Parameters!$K$8),Parameters!$G$8) -> 16.179642 | T24: =MAX(R24-R23,0) -> 1.5129078 | U24: =MAX(S24-S23,0) -> 1.6460175 | V24: =Parameters!$D$9+(Parameters!$G$9-Parameters!$D$9)*((1/(1+EXP(-Parameters!$I$9*($A24-Parameters!$J$9))))-(1/(1+EXP(-Parameters!$I$9*(2024-Parameters!$J$9)))))/(1-(1/(1+EXP(-Parameters!$I$9*(2024-Parameters!$J$9))))) -> 9.5541171 | W24: =MIN(Parameters!$D$9+IF(Parameters!$K$9=0,Parameters!$E$9*($A24-2024),Parameters!$E$9*((1+Parameters!$K$9)^($A24-2024)-1)/Parameters!$K$9),Parameters!$G$9) -> 8.3860176 | X24: =MAX(V24-V23,0) -> 0.98224836 | Y24: =MAX(W24-W23,0) -> 0.70390665 | Z24: =Parameters!$D$10+(Parameters!$G$10-Parameters!$D$10)*((1/(1+EXP(-Parameters!$I$10*($A24-Parameters!$J$10))))-(1/(1+EXP(-Parameters!$I$10*(2024-Parameters!$J$10)))))/(1-(1/(1+EXP(-Parameters!$I$10*(2024-Parameters!$J$10))))) -> 3.2377763 | AA24: =MIN(Parameters!$D$10+IF(Parameters!$K$10=0,Parameters!$E$10*($A24-2024),Parameters!$E$10*((1+Parameters!$K$10)^($A24-2024)-1)/Parameters!$K$10),Parameters!$G$10) -> 3.3214773 | AB24: =MAX(Z24-Z23,0) -> 0.33100236 | AC24: =MAX(AA24-AA23,0) -> 0.30996393 | AD24: =Parameters!$D$11+(Parameters!$G$11-Parameters!$D$11)*((1/(1+EXP(-Parameters!$I$11*($A24-Parameters!$J$11))))-(1/(1+EXP(-Parameters!$I$11*(2024-Parameters!$J$11)))))/(1-(1/(1+EXP(-Parameters!$I$11*(2024-Parameters!$J$11))))) -> 7.853706 | AE24: =MIN(Parameters!$D$11+IF(Parameters!$K$11=0,Parameters!$E$11*($A24-2024),Parameters!$E$11*((1+Parameters!$K$11)^($A24-2024)-1)/Parameters!$K$11),Parameters!$G$11) -> 6.7128343 | AF24: =MAX(AD24-AD23,0) -> 0.7319004 | AG24: =MAX(AE24-AE23,0) -> 0.45901137 | AH24: =Parameters!$D$12+(Parameters!$G$12-Parameters!$D$12)*((1/(1+EXP(-Parameters!$I$12*($A24-Parameters!$J$12))))-(1/(1+EXP(-Parameters!$I$12*(2024-Parameters!$J$12)))))/(1-(1/(1+EXP(-Parameters!$I$12*(2024-Parameters!$J$12))))) -> 5.6964287 | AI24: =MIN(Parameters!$D$12+IF(Parameters!$K$12=0,Parameters!$E$12*($A24-2024),Parameters!$E$12*((1+Parameters!$K$12)^($A24-2024)-1)/Parameters!$K$12),Parameters!$G$12) -> 4.5096064 | AJ24: =MAX(AH24-AH23,0) -> 0.97683024 | AK24: =MAX(AI24-AI23,0) -> 0.65064604 | AL24: =Parameters!$D$13+(Parameters!$G$13-Parameters!$D$13)*((1/(1+EXP(-Parameters!$I$13*($A24-Parameters!$J$13))))-(1/(1+EXP(-Parameters!$I$13*(2024-Parameters!$J$13)))))/(1-(1/(1+EXP(-Parameters!$I$13*(2024-Parameters!$J$13))))) -> 1.5305553 | AM24: =MIN(Parameters!$D$13+IF(Parameters!$K$13=0,Parameters!$E$13*($A24-2024),Parameters!$E$13*((1+Parameters!$K$13)^($A24-2024)-1)/Parameters!$K$13),Parameters!$G$13) -> 0.07237805 | AN24: =MAX(AL24-AL23,0) -> 0.33612569 | AO24: =MAX(AM24-AM23,0) -> 0.00805255 | AP24: =Parameters!$D$14+(Parameters!$G$14-Parameters!$D$14)*((1/(1+EXP(-Parameters!$I$14*($A24-Parameters!$J$14))))-(1/(1+EXP(-Parameters!$I$14*(2024-Parameters!$J$14)))))/(1-(1/(1+EXP(-Parameters!$I$14*(2024-Parameters!$J$14))))) -> 1.6181488 | AQ24: =MIN(Parameters!$D$14+IF(Parameters!$K$14=0,Parameters!$E$14*($A24-2024),Parameters!$E$14*((1+Parameters!$K$14)^($A24-2024)-1)/Parameters!$K$14),Parameters!$G$14) -> 1.0292147 | AR24: =MAX(AP24-AP23,0) -> 0.24108125 | AS24: =MAX(AQ24-AQ23,0) -> 0.10468315 | AT24: =Parameters!$D$15+(Parameters!$G$15-Parameters!$D$15)*((1/(1+EXP(-Parameters!$I$15*($A24-Parameters!$J$15))))-(1/(1+EXP(-Parameters!$I$15*(2024-Parameters!$J$15)))))/(1-(1/(1+EXP(-Parameters!$I$15*(2024-Parameters!$J$15))))) -> 1.9792684 | AU24: =MIN(Parameters!$D$15+IF(Parameters!$K$15=0,Parameters!$E$15*($A24-2024),Parameters!$E$15*((1+Parameters!$K$15)^($A24-2024)-1)/Parameters!$K$15),Parameters!$G$15) -> 2.9626745 | AV24: =MAX(AT24-AT23,0) -> 0.17162747 | AW24: =MAX(AU24-AU23,0) -> 0.36292403
